Workbook
Name Ability_Component_Tags: _xlfn.ANCHORARRAY(tags!$B$2)
Name Action_Tags: _xlfn.ANCHORARRAY(tags!$D$2)
Name Attack_Tags: _xlfn.ANCHORARRAY(tags!$E$2)
Name Bonus_Action_Tags: _xlfn.ANCHORARRAY(tags!$K$2)
Name Condition_Effect_Tags: _xlfn.ANCHORARRAY(tags!$F$2)
Name Damage_Effect_Tags: _xlfn.ANCHORARRAY(tags!$G$2)
Name Duration_Descs: durations!$D$2:$D$125
Name Duration_Names: durations!$B$2:$B$125
Name Feature_Ability_Tags: _xlfn.ANCHORARRAY(tags!$A$2)
Name Filtered_Templates: _xlfn.ANCHORARRAY(tags!#REF!)
Name Outcome_Tags: _xlfn.ANCHORARRAY(tags!$C$2)
Name Reaction_Tags: _xlfn.ANCHORARRAY(tags!$L$2)
Name Save_Effect_Tags: _xlfn.ANCHORARRAY(tags!$H$2)
Name Secondary_Effect_Tags: _xlfn.ANCHORARRAY(tags!$I$2)
Name Target_Effect_Tags: _xlfn.ANCHORARRAY(tags!$J$2)

Sheet ASSEMBLY
A1: ok | B1: [#]
A2: ok | B2: [#dX]
A3: ok | B3: [DISEASE]
A4: ok | B4: [DMG_EFFECT]
A5: ok | B5: [DMG_MOD]
A6: ok | B6: [DMG_TYPE]
A7: ok | B7: [DURATION]
A9: ok | B9: [MON]
A10: ok | B10: [OUTCOME]
A12: ok | B12: [SAVE_DC]
A13: ok | B13: [ABILITY]
A15: ok | B15: [TGT_EFFECT]

Sheet tags
A1: Feature/Ability Tags | B1: Add-On Tags | C1: Outcome Tags | D1: Action Tags | E1: Attack Effect Tags | F1: Condition Effect Tags | G1: Damage Effect Tags | H1: Save Effect Tags | I1: Secondary Effect Tags | J1: Target Effect Tags | K1: Bonus Action Tags | L1: Reaction Tags
A2: {=_xlfn._xlws.SORT(_xlfn.UNIQUE(TRIM(_xlfn.TOCOL(_xlfn.TEXTSPLIT('features-abilities'!$C$2:$C$2000,",",,TRUE),3))))} -> Ability Score Damage | B2: {=_xlfn._xlws.SORT(_xlfn.UNIQUE(TRIM(_xlfn.TOCOL(_xlfn.TEXTSPLIT('add-ons'!$C$2:$C$2000,",",,TRUE),3))))} -> Ability Score Damage | C2: {=_xlfn._xlws.SORT(_xlfn.UNIQUE(TRIM(_xlfn.TOCOL(_xlfn.TEXTSPLIT(outcomes!$C$2:$C$1999,",",,TRUE),3))))} -> Ability Score Damage | D2: {=_xlfn._xlws.SORT(_xlfn.UNIQUE(TRIM(_xlfn.TOCOL(_xlfn.TEXTSPLIT(actions!$C$2:$C$2000,",",,TRUE),3))))} -> Ability Score Damage | E2: {=_xlfn._xlws.SORT(_xlfn.UNIQUE(TRIM(_xlfn.TOCOL(_xlfn.TEXTSPLIT('attack effects'!$C$2:$C$2000,",",,TRUE),3))))} -> Advantage | F2: {=_xlfn._xlws.SORT(_xlfn.UNIQUE(TRIM(_xlfn.TOCOL(_xlfn.TEXTSPLIT('condition effects'!$C$2:$C$2000,",",,TRUE),3))))} -> Ability Score Damage | G2: {=_xlfn._xlws.SORT(_xlfn.UNIQUE(TRIM(_xlfn.TOCOL(_xlfn.TEXTSPLIT('damage effects'!$C$2:$C$2000,",",,TRUE),3))))} -> Ability Score Damage | H2: {=_xlfn._xlws.SORT(_xlfn.UNIQUE(TRIM(_xlfn.TOCOL(_xlfn.TEXTSPLIT('save effects'!$C$2:$C$2000,",",,TRUE),3))))} -> Advantage | I2: {=_xlfn._xlws.SORT(_xlfn.UNIQUE(TRIM(_xlfn.TOCOL(_xlfn.TEXTSPLIT('secondary effects'!$C$2:$C$2000,",",,TRUE),3))))} -> AC Change | J2: {=_xlfn._xlws.SORT(_xlfn.UNIQUE(TRIM(_xlfn.TOCOL(_xlfn.TEXTSPLIT('target effects'!$C$2:$C$2000,",",,TRUE),3))))} -> Ability Score Damage | K2: {=_xlfn._xlws.SORT(_xlfn.UNIQUE(TRIM(_xlfn.TOCOL(_xlfn.TEXTSPLIT('bonus actions'!$C$2:$C$2000,",",,TRUE),3))))} -> Ability Score Damage | L2: {=_xlfn._xlws.SORT(_xlfn.UNIQUE(TRIM(_xlfn.TOCOL(_xlfn.TEXTSPLIT(reactions!$C$2:$C$2000,",",,TRUE),3))))} -> AC Change
A3: AC Change | B3: AC Change | C3: AC Change | D3: AC Change | E3: Area | F3: Advantage | G3: Advantage | H3: Charm Effect | I3: Bonus Action Attack | J3: AC Change | K3: AC Change | L3: Advantage
A4: Advantage | B4: Advantage | C4: Advantage | D4: Advantage | E4: Attachment Effect | F4: Approaching | G4: Aging | H4: Charming | I4: Charm Effect | J4: Advantage | K4: Advantage | L4: Area
A5: Aging | B5: Aging | C5: Aging | D5: Approaching | E5: Bonus Action Attack | F5: Attachment Effect | G5: Area | H5: Confusion | I5: Consumption Ending | J5: Area | K5: Approaching | L5: Aura
A6: Approaching | B6: Approaching | C6: Approaching | D6: Area | E6: Concentration | F6: Attachment Ending | G6: Bonus Action Attack | H6: Curse Effect | I6: Curse Effect | J6: Attaching | K6: Area | L6: Betraying
A7: Area | B7: Area | C7: Area | D7: Attaching | E7: Consuming | F7: Aura | G7: Disadvantage | H7: Disadvantage | I7: Disengaging | J7: Bonus Action Attack | K7: Aura | L7: Blinding
A8: Attaching | B8: Attachment Effect | C8: Betraying | D8: Aura | E8: Cursing | F8: Betraying | G8: Disarming | H8: Discharging | I8: Extra Damage | J8: Coating | K8: Betraying | L8: Charm Effect
A9: Aura | B9: Attachment Ending | C9: Blinding | D9: Betraying | E9: Disadvantage | F9: Blinding | G9: Equipment Damage | H9: Fear Effect | I9: Fear Effect | J9: Consuming | K9: Blinding | L9: Charming
A10: Blinding | B10: Aura | C10: Bonus Action Attack | D10: Blinding | E10: Discharging | F10: Blindness Ending | G10: Exhausting | H10: Limitation | I10: Grapple Effect | J10: Disadvantage | K10: Bonus Action Attack | L10: Consumption Effect
A11: Blindness Effect | B11: Betraying | C11: Charming | D11: Bonus Action Attack | E11: Disengaging | F11: Can't Attack Other Targets | G11: Extra Damage | I11: HP Max Reducing | J11: Disengaging | K11: Charming | L11: Cursing
A12: Bonus Action Attack | B12: Blinding | C12: Coating | D12: Charm Effect | E12: Equipment Damage | F12: Charm Effect | G12: Grapple Effect | I12: Incapacitation Effect | J12: Equipment Damage | K12: Communication | L12: Damage Reduction
A13: Charming | B13: Blindness Ending | C13: Confusing | D13: Charming | E13: Expanded Crit Range | F13: Charm Ending | G13: Healing | I13: Infecting | J13: Extra Damage | K13: Consumption Effect | L13: Difficult Terrain
A14: Coating | B14: Bonus Action Attack | C14: Consuming | D14: Coating | E14: Extra Damage | F14: Charming | G14: HP Max Reducing | I14: Limitation | J14: HP Max Reducing | K14: Cursing | L14: Disadvantage
A15: Communication | B15: Can't Attack Other Targets | C15: Cursing | D15: Communication | E15: Grapple Effect | F15: Confusing | G15: Knockout | I15: Magic Disrupting | J15: Magic Disrupting | K15: Damage Reduction | L15: Disarming
A16: Concentration | B16: Charm Effect | C16: Damage Reduction | D16: Concentration | E16: Grappling | F16: Confusion | G16: Lethal | I16: Movement | J16: Nonreactive | K16: Difficult Terrain | L16: Disengaging
A17: Confusing | B17: Charm Ending | C17: Deafening | D17: Confusing | E17: HP Max Reducing | F17: Confusion Ending | G17: Limitation | I17: Obscuring | J17: Ongoing Damage | K17: Disadvantage | L17: Drop to 0
A18: Consuming | B18: Charming | C18: Disadvantage | D18: Consuming | E18: Incapacitating | F18: Consumption Effect | G18: Nonlethal | I18: Poison Effect | J18: Paralyzing | K18: Discharging | L18: Extra Damage
A19: Curse Effect | B19: Communication | C19: Disarming | D19: Curse Effect | E19: Infecting | F19: Consumption Ending | G19: Self Healing | I19: Prone Effect | J19: Pushing | K19: Disengaging | L19: Frightening
A20: Cursing | B20: Concentration | C20: Drop to 0 | D20: Cursing | E20: Injury | F20: Curse Effect | G20: Shapechanging | I20: Pushing | J20: Shapechanging | K20: Equipment Damage | L20: Gaze
A21: Damage Reduction | B21: Confusing | C21: Effect Ending | D21: Damage Reduction | E21: Lethal | F21: Curse Ending | G21: Spawning | I21: Restraining | J21: Speed Change | K21: Exhausting | L21: Grappling
A22: Deafening | B22: Confusion | C22: Exhausting | D22: Deafening | E22: Light | F22: Cursing | G22: Temporary Self Healing | I22: Restraint Effect | J22: Suffocating | K22: Expanded Crit Range | L22: Healing
A23: Difficult Terrain | B23: Confusion Ending | C23: Extra Damage | D23: Difficult Terrain | E23: Limitation | F23: Damage Reduction | I23: Self Healing | J23: Summoning | K23: Extra Damage | L23: Incapacitating
A24: Disadvantage | B24: Consuming | C24: Frightening | D24: Disadvantage | E24: Magic Disrupting | F24: Deafness Ending | I24: Stun Effect | J24: Teleportation | K24: Grapple Effect | L24: Invisible
A25: Disarming | B25: Consumption Effect | C25: Grappling | D25: Disarming | E25: Mount | F25: Disadvantage | I25: Temporary Self Healing | J25: Zero Speed | K25: Grappling | L25: Light
A26: Discharging | B26: Consumption Ending | C26: Healing | D26: Discharging | E26: Movement | F26: Disease | I26: Throwing | K26: Incapacitating | L26: Magic Disrupting
A27: Disengaging | B27: Curse Effect | C27: HP Max Reducing | D27: Disengaging | E27: Ongoing Damage | F27: Effect Ending | I27: Toppling | K27: Infecting | L27: Mount
A28: Drop to 0 | B28: Curse Ending | C28: Incapacitating | D28: Drop to 0 | E28: Poisoning | F28: Exhausting | I28: Unconsciousness Effect | K28: Invisible | L28: Movement
A29: Effect Ending | B29: Cursing | C29: Infecting | D29: Equipment Damage | E29: Rattling | F29: Exhaustion Effect | I29: Weakness | K29: Lethal | L29: Nonreactive
A30: Equipment Damage | B30: Damage Reduction | C30: Knockout | D30: Exhausting | E30: Recharging | F30: Exhaustion Ending | K30: Light | L30: Obscuring
A31: Exhausting | B31: Deafening | C31: Lethal | D31: Frightening | E31: Self Healing | F31: Extra Damage | K31: Magic Disrupting | L31: Ongoing Damage
A32: Expanded Crit Range | B32: Deafness Ending | C32: Madness | D32: Grapple Effect | E32: Shapechanging | F32: Fear Effect | K32: Mount | L32: Poisoning
A33: Extra Damage | B33: Difficult Terrain | C33: Magic Disrupting | D33: Grapple Ending | E33: Spawning | F33: Fear Ending | K33: Movement | L33: Prone Effect
A34: Frightening | B34: Disadvantage | C34: Marking | D34: Grappling | E34: Temporary Healing | F34: Fire Effect | K34: Obscuring | L34: Pushing
A35: Gaze | B35: Disarming | C35: Movement | D35: Healing | E35: Unhealable | F35: Grapple Effect | K35: Ongoing Damage | L35: Recharging
A36: Grapple Effect | B36: Discharging | C36: Nonreactive | D36: HP Max Reducing | E36: Weakness | F36: Grapple Ending | K36: Poisoning | L36: Self Healing
A37: Grappling | B37: Disease | C37: Ongoing Damage | D37: Incapacitating | F37: HP Max Reducing | K37: Possessing | L37: Shapechanging
A38: Healing | B38: Disengaging | C38: Paralyzing | D38: Incapacitation Effect | F38: Incapacitating | K38: Prone Effect | L38: Speed Change
A39: HP Max Reducing | B39: Effect Ending | C39: Petrifying | D39: Infecting | F39: Incapacitation Effect | K39: Pulling | L39: Stunning
A40: Incapacitating | B40: Equipment Damage | C40: Poisoning | D40: Invisible | F40: Incapacitation Ending | K40: Rampaging | L40: Summoning
...

Sheet standard weapons
A1: Type | B1: Weapon | C1: Ability | D1: Reach/Range | E1: Damage Die | F1: Damage Type | G1: Properties | H1: Mastery (2024 only) | I1: Special Text | J1: Template | K1: With Mastery | L1: With Properties | P1: Split | U1: Split 2 | W1: 2 | Y1: 3 | AA1: 4 | AC1: 5
A2: Melee Weapon Attack | B2: Club (2014 edition) | C2: Strength | D2: reach 5 ft | E2: 1d4 | F2: bludgeoning | G2: Light | J2: =A2&": [ATK_MOD] to hit, "&D2&", one target. Hit: [DAMAGE] "&F2&" damage. "&I2 -> Melee Weapon Attack: [ATK_MOD] to hit, reach 5 ft, one target. Hit: [DAMAGE] bludgeoning damage. | L2: =IF(NOT(G2=""),IF(COUNTA(P2:T2)>1,"Properties: ","Property: ")&U2&" ("&V2&")"&IF(NOT(W2=""),", "&W2&" ("&X2&")"&IF(NOT(Y2=""),", "&Y2&" ("&Z2&")"&IF(NOT(AA2=""),", "&AB2&" ("&AC2&")",""),""),""),"") -> Property: Light (A light weapon is small and easy to handle, making it ideal for use when fighting with two weapons.) | P2: {=IFERROR(_xlfn.TEXTSPLIT(G2,", ",,TRUE),"")} -> Light | U2: {=IFERROR(INDEX(_xlfn.TEXTSPLIT(P2," "),,1),"")} -> Light | V2: =IF(NOT(U2=""),_xlfn.XLOOKUP(U2,'weapon masteries'!$A$10:$A$19,'weapon masteries'!$B$10:$B$19,"",0),"") -> A light weapon is small and easy to handle, making it ideal for use when fighting with two weapons. | W2: {=IFERROR(INDEX(_xlfn.TEXTSPLIT(Q2," "),,1),"")} | X2: =IF(NOT(W2=""),_xlfn.XLOOKUP(W2,'weapon masteries'!$A$10:$A$19,'weapon masteries'!$B$10:$B$19,"",0),"") | Y2: {=IFERROR(INDEX(_xlfn.TEXTSPLIT(R2," "),,1),"")} | Z2: =IF(NOT(Y2=""),_xlfn.XLOOKUP(Y2,'weapon masteries'!$A$10:$A$19,'weapon masteries'!$B$10:$B$19,"",0),"") | AA2: {=IFERROR(INDEX(_xlfn.TEXTSPLIT(S2," "),,1),"")} | AB2: =IF(NOT(AA2=""),_xlfn.XLOOKUP(AA2,'weapon masteries'!$A$10:$A$19,'weapon masteries'!$B$10:$B$19,"",0),"") | AC2: {=IFERROR(INDEX(_xlfn.TEXTSPLIT(T2," "),,1),"")} | AD2: =IF(NOT(AC2=""),_xlfn.XLOOKUP(AC2,'weapon masteries'!$A$10:$A$20,'weapon masteries'!$B$10:$B$20,"",0),"")
A3: Melee or Ranged Weapon Attack | B3: Dagger (2014 edition) | C3: Max of Strength or Dexterity | D3: reach 5 ft or range 20/60 ft | E3: 1d4 | F3: piercing | G3: Finesse, Light, Thrown (20/60) | J3: =A3&": [ATK_MOD] to hit, "&D3&", one target. Hit: [DAMAGE] "&F3&" damage. "&I3 -> Melee or Ranged Weapon Attack: [ATK_MOD] to hit, reach 5 ft or range 20/60 ft, one target. Hit: [DAMAGE] piercing damage. | L3: =IF(NOT(G3=""),IF(COUNTA(P3:T3)>1,"Properties: ","Property: ")&U3&" ("&V3&")"&IF(NOT(W3=""),", "&W3&" ("&X3&")"&IF(NOT(Y3=""),", "&Y3&" ("&Z3&")"&IF(NOT(AA3=""),", "&AB3&" ("&AC3&")",""),""),""),"") -> Properties: Finesse (When making an attack with a finesse weapon, you use your choice of your Strength or Dexterity modifier for the attack and damage rolls. You must use the same modifier for both rolls.), Light (A light weapon is small and easy to handle, making it ideal for use when fighting with two weapons.), Thrown (If a weapon has the thrown property, you can throw the weapon to make a ranged attack. If the weapon is a melee weapon, you use the same ability modifier for that attack roll and damage roll that you would use for a melee attack with the weapon. For example, if you throw a handaxe, you use your Strength, but if you throw a dagger, you can use either your Strength or your Dexterity, since the dagger has the finesse property.) | P3: {=IFERROR(_xlfn.TEXTSPLIT(G3,", ",,TRUE),"")} -> Finesse | Q3: Light | R3: Thrown (20/60) | U3: {=IFERROR(INDEX(_xlfn.TEXTSPLIT(P3," "),,1),"")} -> Finesse | V3: =IF(NOT(U3=""),_xlfn.XLOOKUP(U3,'weapon masteries'!$A$10:$A$19,'weapon masteries'!$B$10:$B$19,"",0),"") -> When making an attack with a finesse weapon, you use your choice of your Strength or Dexterity modifier for the attack and damage rolls. You must use the same modifier for both rolls. | W3: {=IFERROR(INDEX(_xlfn.TEXTSPLIT(Q3," "),,1),"")} -> Light | X3: =IF(NOT(W3=""),_xlfn.XLOOKUP(W3,'weapon masteries'!$A$10:$A$19,'weapon masteries'!$B$10:$B$19,"",0),"") -> A light weapon is small and easy to handle, making it ideal for use when fighting with two weapons. | Y3: {=IFERROR(INDEX(_xlfn.TEXTSPLIT(R3," "),,1),"")} -> Thrown | Z3: =IF(NOT(Y3=""),_xlfn.XLOOKUP(Y3,'weapon masteries'!$A$10:$A$19,'weapon masteries'!$B$10:$B$19,"",0),"") -> If a weapon has the thrown property, you can throw the weapon to make a ranged attack. If the weapon is a melee weapon, you use the same ability modifier for that attack roll and damage roll that you would use for a melee attack with the weapon. For example, if you throw a handaxe, you use your Strength, but if you throw a dagger, you can use either your Strength or your Dexterity, since the dagger has the finesse property. | AA3: {=IFERROR(INDEX(_xlfn.TEXTSPLIT(S3," "),,1),"")} | AB3: =IF(NOT(AA3=""),_xlfn.XLOOKUP(AA3,'weapon masteries'!$A$10:$A$19,'weapon masteries'!$B$10:$B$19,"",0),"") | AC3: {=IFERROR(INDEX(_xlfn.TEXTSPLIT(T3," "),,1),"")} | AD3: =IF(NOT(AC3=""),_xlfn.XLOOKUP(AC3,'weapon masteries'!$A$10:$A$20,'weapon masteries'!$B$10:$B$20,"",0),"")
A4: Melee Weapon Attack | B4: Greatclub (2014 edition) | C4: Strength | D4: reach 5 ft target | E4: 1d8 | F4: bludgeoning | G4: Two-Handed | J4: =A4&": [ATK_MOD] to hit, "&D4&", one target. Hit: [DAMAGE] "&F4&" damage. "&I4 -> Melee Weapon Attack: [ATK_MOD] to hit, reach 5 ft target, one target. Hit: [DAMAGE] bludgeoning damage. | L4: =IF(NOT(G4=""),IF(COUNTA(P4:T4)>1,"Properties: ","Property: ")&U4&" ("&V4&")"&IF(NOT(W4=""),", "&W4&" ("&X4&")"&IF(NOT(Y4=""),", "&Y4&" ("&Z4&")"&IF(NOT(AA4=""),", "&AB4&" ("&AC4&")",""),""),""),"") -> Property: Two-Handed (This weapon requires two hands to use. This property is relevant only when you attack with the weapon, not when you simply hold it.) | P4: {=IFERROR(_xlfn.TEXTSPLIT(G4,", ",,TRUE),"")} -> Two-Handed | U4: {=IFERROR(INDEX(_xlfn.TEXTSPLIT(P4," "),,1),"")} -> Two-Handed | V4: =IF(NOT(U4=""),_xlfn.XLOOKUP(U4,'weapon masteries'!$A$10:$A$19,'weapon masteries'!$B$10:$B$19,"",0),"") -> This weapon requires two hands to use. This property is relevant only when you attack with the weapon, not when you simply hold it. | W4: {=IFERROR(INDEX(_xlfn.TEXTSPLIT(Q4," "),,1),"")} | X4: =IF(NOT(W4=""),_xlfn.XLOOKUP(W4,'weapon masteries'!$A$10:$A$19,'weapon masteries'!$B$10:$B$19,"",0),"") | Y4: {=IFERROR(INDEX(_xlfn.TEXTSPLIT(R4," "),,1),"")} | Z4: =IF(NOT(Y4=""),_xlfn.XLOOKUP(Y4,'weapon masteries'!$A$10:$A$19,'weapon masteries'!$B$10:$B$19,"",0),"") | AA4: {=IFERROR(INDEX(_xlfn.TEXTSPLIT(S4," "),,1),"")} | AB4: =IF(NOT(AA4=""),_xlfn.XLOOKUP(AA4,'weapon masteries'!$A$10:$A$19,'weapon masteries'!$B$10:$B$19,"",0),"") | AC4: {=IFERROR(INDEX(_xlfn.TEXTSPLIT(T4," "),,1),"")} | AD4: =IF(NOT(AC4=""),_xlfn.XLOOKUP(AC4,'weapon masteries'!$A$10:$A$20,'weapon masteries'!$B$10:$B$20,"",0),"")
A5: Melee or Ranged Weapon Attack | B5: Handaxe (2014 edition) | C5: Max of Strength or Dexterity | D5: reach 5 ft or range 20/60 ft | E5: 1d6 | F5: slashing | G5: Light, Thrown (20/60) | J5: =A5&": [ATK_MOD] to hit, "&D5&", one target. Hit: [DAMAGE] "&F5&" damage. "&I5 -> Melee or Ranged Weapon Attack: [ATK_MOD] to hit, reach 5 ft or range 20/60 ft, one target. Hit: [DAMAGE] slashing damage. | L5: =IF(NOT(G5=""),IF(COUNTA(P5:T5)>1,"Properties: ","Property: ")&U5&" ("&V5&")"&IF(NOT(W5=""),", "&W5&" ("&X5&")"&IF(NOT(Y5=""),", "&Y5&" ("&Z5&")"&IF(NOT(AA5=""),", "&AB5&" ("&AC5&")",""),""),""),"") -> Properties: Light (A light weapon is small and easy to handle, making it ideal for use when fighting with two weapons.), Thrown (If a weapon has the thrown property, you can throw the weapon to make a ranged attack. If the weapon is a melee weapon, you use the same ability modifier for that attack roll and damage roll that you would use for a melee attack with the weapon. For example, if you throw a handaxe, you use your Strength, but if you throw a dagger, you can use either your Strength or your Dexterity, since the dagger has the finesse property.) | P5: {=IFERROR(_xlfn.TEXTSPLIT(G5,", ",,TRUE),"")} -> Light | Q5: Thrown (20/60) | U5: {=IFERROR(INDEX(_xlfn.TEXTSPLIT(P5," "),,1),"")} -> Light | V5: =IF(NOT(U5=""),_xlfn.XLOOKUP(U5,'weapon masteries'!$A$10:$A$19,'weapon masteries'!$B$10:$B$19,"",0),"") -> A light weapon is small and easy to handle, making it ideal for use when fighting with two weapons. | W5: {=IFERROR(INDEX(_xlfn.TEXTSPLIT(Q5," "),,1),"")} -> Thrown | X5: =IF(NOT(W5=""),_xlfn.XLOOKUP(W5,'weapon masteries'!$A$10:$A$19,'weapon masteries'!$B$10:$B$19,"",0),"") -> If a weapon has the thrown property, you can throw the weapon to make a ranged attack. If the weapon is a melee weapon, you use the same ability modifier for that attack roll and damage roll that you would use for a melee attack with the weapon. For example, if you throw a handaxe, you use your Strength, but if you throw a dagger, you can use either your Strength or your Dexterity, since the dagger has the finesse property. | Y5: {=IFERROR(INDEX(_xlfn.TEXTSPLIT(R5," "),,1),"")} | Z5: =IF(NOT(Y5=""),_xlfn.XLOOKUP(Y5,'weapon masteries'!$A$10:$A$19,'weapon masteries'!$B$10:$B$19,"",0),"") | AA5: {=IFERROR(INDEX(_xlfn.TEXTSPLIT(S5," "),,1),"")} | AB5: =IF(NOT(AA5=""),_xlfn.XLOOKUP(AA5,'weapon masteries'!$A$10:$A$19,'weapon masteries'!$B$10:$B$19,"",0),"") | AC5: {=IFERROR(INDEX(_xlfn.TEXTSPLIT(T5," "),,1),"")} | AD5: =IF(NOT(AC5=""),_xlfn.XLOOKUP(AC5,'weapon masteries'!$A$10:$A$20,'weapon masteries'!$B$10:$B$20,"",0),"")
A6: Melee or Ranged Weapon Attack | B6: Javelin (2014 edition) | C6: Strength | D6: reach 5 ft or range 30/120 ft | E6: 1d6 | F6: piercing | G6: Thrown (30/120) | J6: =A6&": [ATK_MOD] to hit, "&D6&", one target. Hit: [DAMAGE] "&F6&" damage. "&I6 -> Melee or Ranged Weapon Attack: [ATK_MOD] to hit, reach 5 ft or range 30/120 ft, one target. Hit: [DAMAGE] piercing damage. | L6: =IF(NOT(G6=""),IF(COUNTA(P6:T6)>1,"Properties: ","Property: ")&U6&" ("&V6&")"&IF(NOT(W6=""),", "&W6&" ("&X6&")"&IF(NOT(Y6=""),", "&Y6&" ("&Z6&")"&IF(NOT(AA6=""),", "&AB6&" ("&AC6&")",""),""),""),"") -> Property: Thrown (If a weapon has the thrown property, you can throw the weapon to make a ranged attack. If the weapon is a melee weapon, you use the same ability modifier for that attack roll and damage roll that you would use for a melee attack with the weapon. For example, if you throw a handaxe, you use your Strength, but if you throw a dagger, you can use either your Strength or your Dexterity, since the dagger has the finesse property.) | P6: {=IFERROR(_xlfn.TEXTSPLIT(G6,", ",,TRUE),"")} -> Thrown (30/120) | U6: {=IFERROR(INDEX(_xlfn.TEXTSPLIT(P6," "),,1),"")} -> Thrown | V6: =IF(NOT(U6=""),_xlfn.XLOOKUP(U6,'weapon masteries'!$A$10:$A$19,'weapon masteries'!$B$10:$B$19,"",0),"") -> If a weapon has the thrown property, you can throw the weapon to make a ranged attack. If the weapon is a melee weapon, you use the same ability modifier for that attack roll and damage roll that you would use for a melee attack with the weapon. For example, if you throw a handaxe, you use your Strength, but if you throw a dagger, you can use either your Strength or your Dexterity, since the dagger has the finesse property. | W6: {=IFERROR(INDEX(_xlfn.TEXTSPLIT(Q6," "),,1),"")} | X6: =IF(NOT(W6=""),_xlfn.XLOOKUP(W6,'weapon masteries'!$A$10:$A$19,'weapon masteries'!$B$10:$B$19,"",0),"") | Y6: {=IFERROR(INDEX(_xlfn.TEXTSPLIT(R6," "),,1),"")} | Z6: =IF(NOT(Y6=""),_xlfn.XLOOKUP(Y6,'weapon masteries'!$A$10:$A$19,'weapon masteries'!$B$10:$B$19,"",0),"") | AA6: {=IFERROR(INDEX(_xlfn.TEXTSPLIT(S6," "),,1),"")} | AB6: =IF(NOT(AA6=""),_xlfn.XLOOKUP(AA6,'weapon masteries'!$A$10:$A$19,'weapon masteries'!$B$10:$B$19,"",0),"") | AC6: {=IFERROR(INDEX(_xlfn.TEXTSPLIT(T6," "),,1),"")} | AD6: =IF(NOT(AC6=""),_xlfn.XLOOKUP(AC6,'weapon masteries'!$A$10:$A$20,'weapon masteries'!$B$10:$B$20,"",0),"")
A7: Melee or Ranged Weapon Attack | B7: Light Hammer (2014 edition) | C7: Max of Strength or Dexterity | D7: reach 5 ft or range 20/60 ft | E7: 1d4 | F7: bludgeoning | G7: Light, Thrown (20/60) | J7: =A7&": [ATK_MOD] to hit, "&D7&", one target. Hit: [DAMAGE] "&F7&" damage. "&I7 -> Melee or Ranged Weapon Attack: [ATK_MOD] to hit, reach 5 ft or range 20/60 ft, one target. Hit: [DAMAGE] bludgeoning damage. | L7: =IF(NOT(G7=""),IF(COUNTA(P7:T7)>1,"Properties: ","Property: ")&U7&" ("&V7&")"&IF(NOT(W7=""),", "&W7&" ("&X7&")"&IF(NOT(Y7=""),", "&Y7&" ("&Z7&")"&IF(NOT(AA7=""),", "&AB7&" ("&AC7&")",""),""),""),"") -> Properties: Light (A light weapon is small and easy to handle, making it ideal for use when fighting with two weapons.), Thrown (If a weapon has the thrown property, you can throw the weapon to make a ranged attack. If the weapon is a melee weapon, you use the same ability modifier for that attack roll and damage roll that you would use for a melee attack with the weapon. For example, if you throw a handaxe, you use your Strength, but if you throw a dagger, you can use either your Strength or your Dexterity, since the dagger has the finesse property.) | P7: {=IFERROR(_xlfn.TEXTSPLIT(G7,", ",,TRUE),"")} -> Light | Q7: Thrown (20/60) | U7: {=IFERROR(INDEX(_xlfn.TEXTSPLIT(P7," "),,1),"")} -> Light | V7: =IF(NOT(U7=""),_xlfn.XLOOKUP(U7,'weapon masteries'!$A$10:$A$19,'weapon masteries'!$B$10:$B$19,"",0),"") -> A light weapon is small and easy to handle, making it ideal for use when fighting with two weapons. | W7: {=IFERROR(INDEX(_xlfn.TEXTSPLIT(Q7," "),,1),"")} -> Thrown | X7: =IF(NOT(W7=""),_xlfn.XLOOKUP(W7,'weapon masteries'!$A$10:$A$19,'weapon masteries'!$B$10:$B$19,"",0),"") -> If a weapon has the thrown property, you can throw the weapon to make a ranged attack. If the weapon is a melee weapon, you use the same ability modifier for that attack roll and damage roll that you would use for a melee attack with the weapon. For example, if you throw a handaxe, you use your Strength, but if you throw a dagger, you can use either your Strength or your Dexterity, since the dagger has the finesse property. | Y7: {=IFERROR(INDEX(_xlfn.TEXTSPLIT(R7," "),,1),"")} | Z7: =IF(NOT(Y7=""),_xlfn.XLOOKUP(Y7,'weapon masteries'!$A$10:$A$19,'weapon masteries'!$B$10:$B$19,"",0),"") | AA7: {=IFERROR(INDEX(_xlfn.TEXTSPLIT(S7," "),,1),"")} | AB7: =IF(NOT(AA7=""),_xlfn.XLOOKUP(AA7,'weapon masteries'!$A$10:$A$19,'weapon masteries'!$B$10:$B$19,"",0),"") | AC7: {=IFERROR(INDEX(_xlfn.TEXTSPLIT(T7," "),,1),"")} | AD7: =IF(NOT(AC7=""),_xlfn.XLOOKUP(AC7,'weapon masteries'!$A$10:$A$20,'weapon masteries'!$B$10:$B$20,"",0),"")
A8: Melee Weapon Attack | B8: Mace (2014 edition) | C8: Strength | D8: reach 5 ft | E8: 1d6 | F8: bludgeoning | J8: =A8&": [ATK_MOD] to hit, "&D8&", one target. Hit: [DAMAGE] "&F8&" damage. "&I8 -> Melee Weapon Attack: [ATK_MOD] to hit, reach 5 ft, one target. Hit: [DAMAGE] bludgeoning damage. | L8: =IF(NOT(G8=""),IF(COUNTA(P8:T8)>1,"Properties: ","Property: ")&U8&" ("&V8&")"&IF(NOT(W8=""),", "&W8&" ("&X8&")"&IF(NOT(Y8=""),", "&Y8&" ("&Z8&")"&IF(NOT(AA8=""),", "&AB8&" ("&AC8&")",""),""),""),"") | P8: {=IFERROR(_xlfn.TEXTSPLIT(G8,", ",,TRUE),"")} | U8: {=IFERROR(INDEX(_xlfn.TEXTSPLIT(P8," "),,1),"")} | V8: =IF(NOT(U8=""),_xlfn.XLOOKUP(U8,'weapon masteries'!$A$10:$A$19,'weapon masteries'!$B$10:$B$19,"",0),"") | W8: {=IFERROR(INDEX(_xlfn.TEXTSPLIT(Q8," "),,1),"")} | X8: =IF(NOT(W8=""),_xlfn.XLOOKUP(W8,'weapon masteries'!$A$10:$A$19,'weapon masteries'!$B$10:$B$19,"",0),"") | Y8: {=IFERROR(INDEX(_xlfn.TEXTSPLIT(R8," "),,1),"")} | Z8: =IF(NOT(Y8=""),_xlfn.XLOOKUP(Y8,'weapon masteries'!$A$10:$A$19,'weapon masteries'!$B$10:$B$19,"",0),"") | AA8: {=IFERROR(INDEX(_xlfn.TEXTSPLIT(S8," "),,1),"")} | AB8: =IF(NOT(AA8=""),_xlfn.XLOOKUP(AA8,'weapon masteries'!$A$10:$A$19,'weapon masteries'!$B$10:$B$19,"",0),"") | AC8: {=IFERROR(INDEX(_xlfn.TEXTSPLIT(T8," "),,1),"")} | AD8: =IF(NOT(AC8=""),_xlfn.XLOOKUP(AC8,'weapon masteries'!$A$10:$A$20,'weapon masteries'!$B$10:$B$20,"",0),"")
A9: Melee Weapon Attack | B9: Quarterstaff (2014 edition) | C9: Strength | D9: reach 5 ft | E9: 1d6 | F9: bludgeoning | G9: Versatile (1d8) | J9: =A9&": [ATK_MOD] to hit, "&D9&", one target. Hit: [DAMAGE] "&F9&" damage. "&I9 -> Melee Weapon Attack: [ATK_MOD] to hit, reach 5 ft, one target. Hit: [DAMAGE] bludgeoning damage. | L9: =IF(NOT(G9=""),IF(COUNTA(P9:T9)>1,"Properties: ","Property: ")&U9&" ("&V9&")"&IF(NOT(W9=""),", "&W9&" ("&X9&")"&IF(NOT(Y9=""),", "&Y9&" ("&Z9&")"&IF(NOT(AA9=""),", "&AB9&" ("&AC9&")",""),""),""),"") -> Property: Versatile (This weapon can be used with one or two hands. A damage value in parentheses appears with the property—the damage when the weapon is used with two hands to make a melee attack.) | P9: {=IFERROR(_xlfn.TEXTSPLIT(G9,", ",,TRUE),"")} -> Versatile (1d8) | U9: {=IFERROR(INDEX(_xlfn.TEXTSPLIT(P9," "),,1),"")} -> Versatile | V9: =IF(NOT(U9=""),_xlfn.XLOOKUP(U9,'weapon masteries'!$A$10:$A$19,'weapon masteries'!$B$10:$B$19,"",0),"") -> This weapon can be used with one or two hands. A damage value in parentheses appears with the property—the damage when the weapon is used with two hands to make a melee attack. | W9: {=IFERROR(INDEX(_xlfn.TEXTSPLIT(Q9," "),,1),"")} | X9: =IF(NOT(W9=""),_xlfn.XLOOKUP(W9,'weapon masteries'!$A$10:$A$19,'weapon masteries'!$B$10:$B$19,"",0),"") | Y9: {=IFERROR(INDEX(_xlfn.TEXTSPLIT(R9," "),,1),"")} | Z9: =IF(NOT(Y9=""),_xlfn.XLOOKUP(Y9,'weapon masteries'!$A$10:$A$19,'weapon masteries'!$B$10:$B$19,"",0),"") | AA9: {=IFERROR(INDEX(_xlfn.TEXTSPLIT(S9," "),,1),"")} | AB9: =IF(NOT(AA9=""),_xlfn.XLOOKUP(AA9,'weapon masteries'!$A$10:$A$19,'weapon masteries'!$B$10:$B$19,"",0),"") | AC9: {=IFERROR(INDEX(_xlfn.TEXTSPLIT(T9," "),,1),"")} | AD9: =IF(NOT(AC9=""),_xlfn.XLOOKUP(AC9,'weapon masteries'!$A$10:$A$20,'weapon masteries'!$B$10:$B$20,"",0),"")
A10: Melee Weapon Attack | B10: Sickle (2014 edition) | C10: Max of Strength or Dexterity | D10: reach 5 ft | E10: 1d4 | F10: slashing | G10: Light | J10: =A10&": [ATK_MOD] to hit, "&D10&", one target. Hit: [DAMAGE] "&F10&" damage. "&I10 -> Melee Weapon Attack: [ATK_MOD] to hit, reach 5 ft, one target. Hit: [DAMAGE] slashing damage. | L10: =IF(NOT(G10=""),IF(COUNTA(P10:T10)>1,"Properties: ","Property: ")&U10&" ("&V10&")"&IF(NOT(W10=""),", "&W10&" ("&X10&")"&IF(NOT(Y10=""),", "&Y10&" ("&Z10&")"&IF(NOT(AA10=""),", "&AB10&" ("&AC10&")",""),""),""),"") -> Property: Light (A light weapon is small and easy to handle, making it ideal for use when fighting with two weapons.) | P10: {=IFERROR(_xlfn.TEXTSPLIT(G10,", ",,TRUE),"")} -> Light | U10: {=IFERROR(INDEX(_xlfn.TEXTSPLIT(P10," "),,1),"")} -> Light | V10: =IF(NOT(U10=""),_xlfn.XLOOKUP(U10,'weapon masteries'!$A$10:$A$19,'weapon masteries'!$B$10:$B$19,"",0),"") -> A light weapon is small and easy to handle, making it ideal for use when fighting with two weapons. | W10: {=IFERROR(INDEX(_xlfn.TEXTSPLIT(Q10," "),,1),"")} | X10: =IF(NOT(W10=""),_xlfn.XLOOKUP(W10,'weapon masteries'!$A$10:$A$19,'weapon masteries'!$B$10:$B$19,"",0),"") | Y10: {=IFERROR(INDEX(_xlfn.TEXTSPLIT(R10," "),,1),"")} | Z10: =IF(NOT(Y10=""),_xlfn.XLOOKUP(Y10,'weapon masteries'!$A$10:$A$19,'weapon masteries'!$B$10:$B$19,"",0),"") | AA10: {=IFERROR(INDEX(_xlfn.TEXTSPLIT(S10," "),,1),"")} | AB10: =IF(NOT(AA10=""),_xlfn.XLOOKUP(AA10,'weapon masteries'!$A$10:$A$19,'weapon masteries'!$B$10:$B$19,"",0),"") | AC10: {=IFERROR(INDEX(_xlfn.TEXTSPLIT(T10," "),,1),"")} | AD10: =IF(NOT(AC10=""),_xlfn.XLOOKUP(AC10,'weapon masteries'!$A$10:$A$20,'weapon masteries'!$B$10:$B$20,"",0),"")
A11: Melee or Ranged Weapon Attack | B11: Spear (2014 edition) | C11: Strength | D11: reach 5 ft or range 20/60 ft | E11: 1d6 | F11: piercing | G11: Thrown (20/60), Versatile (1d8) | J11: =A11&": [ATK_MOD] to hit, "&D11&", one target. Hit: [DAMAGE] "&F11&" damage. "&I11 -> Melee or Ranged Weapon Attack: [ATK_MOD] to hit, reach 5 ft or range 20/60 ft, one target. Hit: [DAMAGE] piercing damage. | L11: =IF(NOT(G11=""),IF(COUNTA(P11:T11)>1,"Properties: ","Property: ")&U11&" ("&V11&")"&IF(NOT(W11=""),", "&W11&" ("&X11&")"&IF(NOT(Y11=""),", "&Y11&" ("&Z11&")"&IF(NOT(AA11=""),", "&AB11&" ("&AC11&")",""),""),""),"") -> Properties: Thrown (If a weapon has the thrown property, you can throw the weapon to make a ranged attack. If the weapon is a melee weapon, you use the same ability modifier for that attack roll and damage roll that you would use for a melee attack with the weapon. For example, if you throw a handaxe, you use your Strength, but if you throw a dagger, you can use either your Strength or your Dexterity, since the dagger has the finesse property.), Versatile (This weapon can be used with one or two hands. A damage value in parentheses appears with the property—the damage when the weapon is used with two hands to make a melee attack.) | P11: {=IFERROR(_xlfn.TEXTSPLIT(G11,", ",,TRUE),"")} -> Thrown (20/60) | Q11: Versatile (1d8) | U11: {=IFERROR(INDEX(_xlfn.TEXTSPLIT(P11," "),,1),"")} -> Thrown | V11: =IF(NOT(U11=""),_xlfn.XLOOKUP(U11,'weapon masteries'!$A$10:$A$19,'weapon masteries'!$B$10:$B$19,"",0),"") -> If a weapon has the thrown property, you can throw the weapon to make a ranged attack. If the weapon is a melee weapon, you use the same ability modifier for that attack roll and damage roll that you would use for a melee attack with the weapon. For example, if you throw a handaxe, you use your Strength, but if you throw a dagger, you can use either your Strength or your Dexterity, since the dagger has the finesse property. | W11: {=IFERROR(INDEX(_xlfn.TEXTSPLIT(Q11," "),,1),"")} -> Versatile | X11: =IF(NOT(W11=""),_xlfn.XLOOKUP(W11,'weapon masteries'!$A$10:$A$19,'weapon masteries'!$B$10:$B$19,"",0),"") -> This weapon can be used with one or two hands. A damage value in parentheses appears with the property—the damage when the weapon is used with two hands to make a melee attack. | Y11: {=IFERROR(INDEX(_xlfn.TEXTSPLIT(R11," "),,1),"")} | Z11: =IF(NOT(Y11=""),_xlfn.XLOOKUP(Y11,'weapon masteries'!$A$10:$A$19,'weapon masteries'!$B$10:$B$19,"",0),"") | AA11: {=IFERROR(INDEX(_xlfn.TEXTSPLIT(S11," "),,1),"")} | AB11: =IF(NOT(AA11=""),_xlfn.XLOOKUP(AA11,'weapon masteries'!$A$10:$A$19,'weapon masteries'!$B$10:$B$19,"",0),"") | AC11: {=IFERROR(INDEX(_xlfn.TEXTSPLIT(T11," "),,1),"")} | AD11: =IF(NOT(AC11=""),_xlfn.XLOOKUP(AC11,'weapon masteries'!$A$10:$A$20,'weapon masteries'!$B$10:$B$20,"",0),"")
A12: Ranged Weapon Attack | B12: Light Crossbow (2014 edition) | C12: Dexterity | D12: range 80/320 ft | E12: 1d8 | F12: piercing | G12: Ammunition, Range (80/320), Loading, Two-Handed | J12: =A12&": [ATK_MOD] to hit, "&D12&", one target. Hit: [DAMAGE] "&F12&" damage. "&I12 -> Ranged Weapon Attack: [ATK_MOD] to hit, range 80/320 ft, one target. Hit: [DAMAGE] piercing damage. | L12: =IF(NOT(G12=""),IF(COUNTA(P12:T12)>1,"Properties: ","Property: ")&U12&" ("&V12&")"&IF(NOT(W12=""),", "&W12&" ("&X12&")"&IF(NOT(Y12=""),", "&Y12&" ("&Z12&")"&IF(NOT(AA12=""),", "&AB12&" ("&AC12&")",""),""),""),"") -> Properties: Ammunition (You can use a weapon that has the ammunition property to make a ranged attack only if you have ammunition to fire from the weapon. Each time you attack with the weapon, you expend one piece of ammunition. Drawing the ammunition from a quiver, case, or other container is part of the attack. Loading a one-handed weapon requires a free hand. At the end of the battle, you can recover half your expended ammunition by taking a minute to search the battlefield. If you use a weapon that has the ammunition property to make a melee attack, you treat the weapon as an improvised weapon. A sling must be loaded to deal any damage when used in this way.), Range (A weapon that can be used to make a ranged attack has a range shown in parentheses after the ammunition or thrown property. The range lists two numbers. The first is the weapon’s normal range in feet, and the second indicates the weapon’s maximum range. When attacking a target beyond normal range, you have disadvantage on the attack roll. You can’t attack a target beyond the weapon’s long range.), Loading (Because of the time required to load this weapon, you can fire only one piece of ammunition from it when you use an action, bonus action, or reaction to fire it, regardless of the number of attacks you can normally make.), This weapon requires two hands to use. This property is relevant only when you attack with the weapon, not when you simply hold it. () | P12: {=IFERROR(_xlfn.TEXTSPLIT(G12,", ",,TRUE),"")} -> Ammunition | Q12: Range (80/320) | R12: Loading | S12: Two-Handed | U12: {=IFERROR(INDEX(_xlfn.TEXTSPLIT(P12," "),,1),"")} -> Ammunition | V12: =IF(NOT(U12=""),_xlfn.XLOOKUP(U12,'weapon masteries'!$A$10:$A$19,'weapon masteries'!$B$10:$B$19,"",0),"") -> You can use a weapon that has the ammunition property to make a ranged attack only if you have ammunition to fire from the weapon. Each time you attack with the weapon, you expend one piece of ammunition. Drawing the ammunition from a quiver, case, or other container is part of the attack. Loading a one-handed weapon requires a free hand. At the end of the battle, you can recover half your expended ammunition by taking a minute to search the battlefield. If you use a weapon that has the ammunition property to make a melee attack, you treat the weapon as an improvised weapon. A sling must be loaded to deal any damage when used in this way. | W12: {=IFERROR(INDEX(_xlfn.TEXTSPLIT(Q12," "),,1),"")} -> Range | X12: =IF(NOT(W12=""),_xlfn.XLOOKUP(W12,'weapon masteries'!$A$10:$A$19,'weapon masteries'!$B$10:$B$19,"",0),"") -> A weapon that can be used to make a ranged attack has a range shown in parentheses after the ammunition or thrown property. The range lists two numbers. The first is the weapon’s normal range in feet, and the second indicates the weapon’s maximum range. When attacking a target beyond normal range, you have disadvantage on the attack roll. You can’t attack a target beyond the weapon’s long range. | Y12: {=IFERROR(INDEX(_xlfn.TEXTSPLIT(R12," "),,1),"")} -> Loading | Z12: =IF(NOT(Y12=""),_xlfn.XLOOKUP(Y12,'weapon masteries'!$A$10:$A$19,'weapon masteries'!$B$10:$B$19,"",0),"") -> Because of the time required to load this weapon, you can fire only one piece of ammunition from it when you use an action, bonus action, or reaction to fire it, regardless of the number of attacks you can normally make. | AA12: {=IFERROR(INDEX(_xlfn.TEXTSPLIT(S12," "),,1),"")} -> Two-Handed | AB12: =IF(NOT(AA12=""),_xlfn.XLOOKUP(AA12,'weapon masteries'!$A$10:$A$19,'weapon masteries'!$B$10:$B$19,"",0),"") -> This weapon requires two hands to use. This property is relevant only when you attack with the weapon, not when you simply hold it. | AC12: {=IFERROR(INDEX(_xlfn.TEXTSPLIT(T12," "),,1),"")} | AD12: =IF(NOT(AC12=""),_xlfn.XLOOKUP(AC12,'weapon masteries'!$A$10:$A$20,'weapon masteries'!$B$10:$B$20,"",0),"")
A13: Ranged Weapon Attack | B13: Dart (2014 edition) | C13: Dexterity | D13: range 20/60 ft | E13: 1d4 | F13: piercing | G13: Finesse, Thrown (20/60) | J13: =A13&": [ATK_MOD] to hit, "&D13&", one target. Hit: [DAMAGE] "&F13&" damage. "&I13 -> Ranged Weapon Attack: [ATK_MOD] to hit, range 20/60 ft, one target. Hit: [DAMAGE] piercing damage. | L13: =IF(NOT(G13=""),IF(COUNTA(P13:T13)>1,"Properties: ","Property: ")&U13&" ("&V13&")"&IF(NOT(W13=""),", "&W13&" ("&X13&")"&IF(NOT(Y13=""),", "&Y13&" ("&Z13&")"&IF(NOT(AA13=""),", "&AB13&" ("&AC13&")",""),""),""),"") -> Properties: Finesse (When making an attack with a finesse weapon, you use your choice of your Strength or Dexterity modifier for the attack and damage rolls. You must use the same modifier for both rolls.), Thrown (If a weapon has the thrown property, you can throw the weapon to make a ranged attack. If the weapon is a melee weapon, you use the same ability modifier for that attack roll and damage roll that you would use for a melee attack with the weapon. For example, if you throw a handaxe, you use your Strength, but if you throw a dagger, you can use either your Strength or your Dexterity, since the dagger has the finesse property.) | P13: {=IFERROR(_xlfn.TEXTSPLIT(G13,", ",,TRUE),"")} -> Finesse | Q13: Thrown (20/60) | U13: {=IFERROR(INDEX(_xlfn.TEXTSPLIT(P13," "),,1),"")} -> Finesse | V13: =IF(NOT(U13=""),_xlfn.XLOOKUP(U13,'weapon masteries'!$A$10:$A$19,'weapon masteries'!$B$10:$B$19,"",0),"") -> When making an attack with a finesse weapon, you use your choice of your Strength or Dexterity modifier for the attack and damage rolls. You must use the same modifier for both rolls. | W13: {=IFERROR(INDEX(_xlfn.TEXTSPLIT(Q13," "),,1),"")} -> Thrown | X13: =IF(NOT(W13=""),_xlfn.XLOOKUP(W13,'weapon masteries'!$A$10:$A$19,'weapon masteries'!$B$10:$B$19,"",0),"") -> If a weapon has the thrown property, you can throw the weapon to make a ranged attack. If the weapon is a melee weapon, you use the same ability modifier for that attack roll and damage roll that you would use for a melee attack with the weapon. For example, if you throw a handaxe, you use your Strength, but if you throw a dagger, you can use either your Strength or your Dexterity, since the dagger has the finesse property. | Y13: {=IFERROR(INDEX(_xlfn.TEXTSPLIT(R13," "),,1),"")} | Z13: =IF(NOT(Y13=""),_xlfn.XLOOKUP(Y13,'weapon masteries'!$A$10:$A$19,'weapon masteries'!$B$10:$B$19,"",0),"") | AA13: {=IFERROR(INDEX(_xlfn.TEXTSPLIT(S13," "),,1),"")} | AB13: =IF(NOT(AA13=""),_xlfn.XLOOKUP(AA13,'weapon masteries'!$A$10:$A$19,'weapon masteries'!$B$10:$B$19,"",0),"") | AC13: {=IFERROR(INDEX(_xlfn.TEXTSPLIT(T13," "),,1),"")} | AD13: =IF(NOT(AC13=""),_xlfn.XLOOKUP(AC13,'weapon masteries'!$A$10:$A$20,'weapon masteries'!$B$10:$B$20,"",0),"")
A14: Ranged Weapon Attack | B14: Shortbow (2014 edition) | C14: Dexterity | D14: range 80/320 ft | E14: 1d6 | F14: piercing | G14: Ammunition, Range (80/320), Two-Handed | J14: =A14&": [ATK_MOD] to hit, "&D14&", one target. Hit: [DAMAGE] "&F14&" damage. "&I14 -> Ranged Weapon Attack: [ATK_MOD] to hit, range 80/320 ft, one target. Hit: [DAMAGE] piercing damage. | L14: =IF(NOT(G14=""),IF(COUNTA(P14:T14)>1,"Properties: ","Property: ")&U14&" ("&V14&")"&IF(NOT(W14=""),", "&W14&" ("&X14&")"&IF(NOT(Y14=""),", "&Y14&" ("&Z14&")"&IF(NOT(AA14=""),", "&AB14&" ("&AC14&")",""),""),""),"") -> Properties: Ammunition (You can use a weapon that has the ammunition property to make a ranged attack only if you have ammunition to fire from the weapon. Each time you attack with the weapon, you expend one piece of ammunition. Drawing the ammunition from a quiver, case, or other container is part of the attack. Loading a one-handed weapon requires a free hand. At the end of the battle, you can recover half your expended ammunition by taking a minute to search the battlefield. If you use a weapon that has the ammunition property to make a melee attack, you treat the weapon as an improvised weapon. A sling must be loaded to deal any damage when used in this way.), Range (A weapon that can be used to make a ranged attack has a range shown in parentheses after the ammunition or thrown property. The range lists two numbers. The first is the weapon’s normal range in feet, and the second indicates the weapon’s maximum range. When attacking a target beyond normal range, you have disadvantage on the attack roll. You can’t attack a target beyond the weapon’s long range.), Two-Handed (This weapon requires two hands to use. This property is relevant only when you attack with the weapon, not when you simply hold it.) | P14: {=IFERROR(_xlfn.TEXTSPLIT(G14,", ",,TRUE),"")} -> Ammunition | Q14: Range (80/320) | R14: Two-Handed | U14: {=IFERROR(INDEX(_xlfn.TEXTSPLIT(P14," "),,1),"")} -> Ammunition | V14: =IF(NOT(U14=""),_xlfn.XLOOKUP(U14,'weapon masteries'!$A$10:$A$19,'weapon masteries'!$B$10:$B$19,"",0),"") -> You can use a weapon that has the ammunition property to make a ranged attack only if you have ammunition to fire from the weapon. Each time you attack with the weapon, you expend one piece of ammunition. Drawing the ammunition from a quiver, case, or other container is part of the attack. Loading a one-handed weapon requires a free hand. At the end of the battle, you can recover half your expended ammunition by taking a minute to search the battlefield. If you use a weapon that has the ammunition property to make a melee attack, you treat the weapon as an improvised weapon. A sling must be loaded to deal any damage when used in this way. | W14: {=IFERROR(INDEX(_xlfn.TEXTSPLIT(Q14," "),,1),"")} -> Range | X14: =IF(NOT(W14=""),_xlfn.XLOOKUP(W14,'weapon masteries'!$A$10:$A$19,'weapon masteries'!$B$10:$B$19,"",0),"") -> A weapon that can be used to make a ranged attack has a range shown in parentheses after the ammunition or thrown property. The range lists two numbers. The first is the weapon’s normal range in feet, and the second indicates the weapon’s maximum range. When attacking a target beyond normal range, you have disadvantage on the attack roll. You can’t attack a target beyond the weapon’s long range. | Y14: {=IFERROR(INDEX(_xlfn.TEXTSPLIT(R14," "),,1),"")} -> Two-Handed | Z14: =IF(NOT(Y14=""),_xlfn.XLOOKUP(Y14,'weapon masteries'!$A$10:$A$19,'weapon masteries'!$B$10:$B$19,"",0),"") -> This weapon requires two hands to use. This property is relevant only when you attack with the weapon, not when you simply hold it. | AA14: {=IFERROR(INDEX(_xlfn.TEXTSPLIT(S14," "),,1),"")} | AB14: =IF(NOT(AA14=""),_xlfn.XLOOKUP(AA14,'weapon masteries'!$A$10:$A$19,'weapon masteries'!$B$10:$B$19,"",0),"") | AC14: {=IFERROR(INDEX(_xlfn.TEXTSPLIT(T14," "),,1),"")} | AD14: =IF(NOT(AC14=""),_xlfn.XLOOKUP(AC14,'weapon masteries'!$A$10:$A$20,'weapon masteries'!$B$10:$B$20,"",0),"")
A15: Ranged Weapon Attack | B15: Sling (2014 edition) | C15: Dexterity | D15: range 30/120 ft | E15: 1d4 | F15: bludgeoning | G15: Ammunition, Range (30/120) | J15: =A15&": [ATK_MOD] to hit, "&D15&", one target. Hit: [DAMAGE] "&F15&" damage. "&I15 -> Ranged Weapon Attack: [ATK_MOD] to hit, range 30/120 ft, one target. Hit: [DAMAGE] bludgeoning damage. | L15: =IF(NOT(G15=""),IF(COUNTA(P15:T15)>1,"Properties: ","Property: ")&U15&" ("&V15&")"&IF(NOT(W15=""),", "&W15&" ("&X15&")"&IF(NOT(Y15=""),", "&Y15&" ("&Z15&")"&IF(NOT(AA15=""),", "&AB15&" ("&AC15&")",""),""),""),"") -> Properties: Ammunition (You can use a weapon that has the ammunition property to make a ranged attack only if you have ammunition to fire from the weapon. Each time you attack with the weapon, you expend one piece of ammunition. Drawing the ammunition from a quiver, case, or other container is part of the attack. Loading a one-handed weapon requires a free hand. At the end of the battle, you can recover half your expended ammunition by taking a minute to search the battlefield. If you use a weapon that has the ammunition property to make a melee attack, you treat the weapon as an improvised weapon. A sling must be loaded to deal any damage when used in this way.), Range (A weapon that can be used to make a ranged attack has a range shown in parentheses after the ammunition or thrown property. The range lists two numbers. The first is the weapon’s normal range in feet, and the second indicates the weapon’s maximum range. When attacking a target beyond normal range, you have disadvantage on the attack roll. You can’t attack a target beyond the weapon’s long range.) | P15: {=IFERROR(_xlfn.TEXTSPLIT(G15,", ",,TRUE),"")} -> Ammunition | Q15: Range (30/120) | U15: {=IFERROR(INDEX(_xlfn.TEXTSPLIT(P15," "),,1),"")} -> Ammunition | V15: =IF(NOT(U15=""),_xlfn.XLOOKUP(U15,'weapon masteries'!$A$10:$A$19,'weapon masteries'!$B$10:$B$19,"",0),"") -> You can use a weapon that has the ammunition property to make a ranged attack only if you have ammunition to fire from the weapon. Each time you attack with the weapon, you expend one piece of ammunition. Drawing the ammunition from a quiver, case, or other container is part of the attack. Loading a one-handed weapon requires a free hand. At the end of the battle, you can recover half your expended ammunition by taking a minute to search the battlefield. If you use a weapon that has the ammunition property to make a melee attack, you treat the weapon as an improvised weapon. A sling must be loaded to deal any damage when used in this way. | W15: {=IFERROR(INDEX(_xlfn.TEXTSPLIT(Q15," "),,1),"")} -> Range | X15: =IF(NOT(W15=""),_xlfn.XLOOKUP(W15,'weapon masteries'!$A$10:$A$19,'weapon masteries'!$B$10:$B$19,"",0),"") -> A weapon that can be used to make a ranged attack has a range shown in parentheses after the ammunition or thrown property. The range lists two numbers. The first is the weapon’s normal range in feet, and the second indicates the weapon’s maximum range. When attacking a target beyond normal range, you have disadvantage on the attack roll. You can’t attack a target beyond the weapon’s long range. | Y15: {=IFERROR(INDEX(_xlfn.TEXTSPLIT(R15," "),,1),"")} | Z15: =IF(NOT(Y15=""),_xlfn.XLOOKUP(Y15,'weapon masteries'!$A$10:$A$19,'weapon masteries'!$B$10:$B$19,"",0),"") | AA15: {=IFERROR(INDEX(_xlfn.TEXTSPLIT(S15," "),,1),"")} | AB15: =IF(NOT(AA15=""),_xlfn.XLOOKUP(AA15,'weapon masteries'!$A$10:$A$19,'weapon masteries'!$B$10:$B$19,"",0),"") | AC15: {=IFERROR(INDEX(_xlfn.TEXTSPLIT(T15," "),,1),"")} | AD15: =IF(NOT(AC15=""),_xlfn.XLOOKUP(AC15,'weapon masteries'!$A$10:$A$20,'weapon masteries'!$B$10:$B$20,"",0),"")
A16: Melee Weapon Attack | B16: Battleaxe (2014 edition) | C16: Strength | D16: reach 5 ft | E16: 1d8 | F16: slashing | G16: Versatile (1d10) | J16: =A16&": [ATK_MOD] to hit, "&D16&", one target. Hit: [DAMAGE] "&F16&" damage. "&I16 -> Melee Weapon Attack: [ATK_MOD] to hit, reach 5 ft, one target. Hit: [DAMAGE] slashing damage. | L16: =IF(NOT(G16=""),IF(COUNTA(P16:T16)>1,"Properties: ","Property: ")&U16&" ("&V16&")"&IF(NOT(W16=""),", "&W16&" ("&X16&")"&IF(NOT(Y16=""),", "&Y16&" ("&Z16&")"&IF(NOT(AA16=""),", "&AB16&" ("&AC16&")",""),""),""),"") -> Property: Versatile (This weapon can be used with one or two hands. A damage value in parentheses appears with the property—the damage when the weapon is used with two hands to make a melee attack.) | P16: {=IFERROR(_xlfn.TEXTSPLIT(G16,", ",,TRUE),"")} -> Versatile (1d10) | U16: {=IFERROR(INDEX(_xlfn.TEXTSPLIT(P16," "),,1),"")} -> Versatile | V16: =IF(NOT(U16=""),_xlfn.XLOOKUP(U16,'weapon masteries'!$A$10:$A$19,'weapon masteries'!$B$10:$B$19,"",0),"") -> This weapon can be used with one or two hands. A damage value in parentheses appears with the property—the damage when the weapon is used with two hands to make a melee attack. | W16: {=IFERROR(INDEX(_xlfn.TEXTSPLIT(Q16," "),,1),"")} | X16: =IF(NOT(W16=""),_xlfn.XLOOKUP(W16,'weapon masteries'!$A$10:$A$19,'weapon masteries'!$B$10:$B$19,"",0),"") | Y16: {=IFERROR(INDEX(_xlfn.TEXTSPLIT(R16," "),,1),"")} | Z16: =IF(NOT(Y16=""),_xlfn.XLOOKUP(Y16,'weapon masteries'!$A$10:$A$19,'weapon masteries'!$B$10:$B$19,"",0),"") | AA16: {=IFERROR(INDEX(_xlfn.TEXTSPLIT(S16," "),,1),"")} | AB16: =IF(NOT(AA16=""),_xlfn.XLOOKUP(AA16,'weapon masteries'!$A$10:$A$19,'weapon masteries'!$B$10:$B$19,"",0),"") | AC16: {=IFERROR(INDEX(_xlfn.TEXTSPLIT(T16," "),,1),"")} | AD16: =IF(NOT(AC16=""),_xlfn.XLOOKUP(AC16,'weapon masteries'!$A$10:$A$20,'weapon masteries'!$B$10:$B$20,"",0),"")
A17: Melee Weapon Attack | B17: Flail (2014 edition) | C17: Strength | D17: reach 5 ft | E17: 1d8 | F17: bludgeoning | J17: =A17&": [ATK_MOD] to hit, "&D17&", one target. Hit: [DAMAGE] "&F17&" damage. "&I17 -> Melee Weapon Attack: [ATK_MOD] to hit, reach 5 ft, one target. Hit: [DAMAGE] bludgeoning damage. | L17: =IF(NOT(G17=""),IF(COUNTA(P17:T17)>1,"Properties: ","Property: ")&U17&" ("&V17&")"&IF(NOT(W17=""),", "&W17&" ("&X17&")"&IF(NOT(Y17=""),", "&Y17&" ("&Z17&")"&IF(NOT(AA17=""),", "&AB17&" ("&AC17&")",""),""),""),"") | P17: {=IFERROR(_xlfn.TEXTSPLIT(G17,", ",,TRUE),"")} | U17: {=IFERROR(INDEX(_xlfn.TEXTSPLIT(P17," "),,1),"")} | V17: =IF(NOT(U17=""),_xlfn.XLOOKUP(U17,'weapon masteries'!$A$10:$A$19,'weapon masteries'!$B$10:$B$19,"",0),"") | W17: {=IFERROR(INDEX(_xlfn.TEXTSPLIT(Q17," "),,1),"")} | X17: =IF(NOT(W17=""),_xlfn.XLOOKUP(W17,'weapon masteries'!$A$10:$A$19,'weapon masteries'!$B$10:$B$19,"",0),"") | Y17: {=IFERROR(INDEX(_xlfn.TEXTSPLIT(R17," "),,1),"")} | Z17: =IF(NOT(Y17=""),_xlfn.XLOOKUP(Y17,'weapon masteries'!$A$10:$A$19,'weapon masteries'!$B$10:$B$19,"",0),"") | AA17: {=IFERROR(INDEX(_xlfn.TEXTSPLIT(S17," "),,1),"")} | AB17: =IF(NOT(AA17=""),_xlfn.XLOOKUP(AA17,'weapon masteries'!$A$10:$A$19,'weapon masteries'!$B$10:$B$19,"",0),"") | AC17: {=IFERROR(INDEX(_xlfn.TEXTSPLIT(T17," "),,1),"")} | AD17: =IF(NOT(AC17=""),_xlfn.XLOOKUP(AC17,'weapon masteries'!$A$10:$A$20,'weapon masteries'!$B$10:$B$20,"",0),"")
A18: Melee Weapon Attack | B18: Glaive (2014 edition) | C18: Strength | D18: reach 10 ft | E18: 1d10 | F18: slashing | G18: Heavy, Reach, Two-Handed | J18: =A18&": [ATK_MOD] to hit, "&D18&", one target. Hit: [DAMAGE] "&F18&" damage. "&I18 -> Melee Weapon Attack: [ATK_MOD] to hit, reach 10 ft, one target. Hit: [DAMAGE] slashing damage. | L18: =IF(NOT(G18=""),IF(COUNTA(P18:T18)>1,"Properties: ","Property: ")&U18&" ("&V18&")"&IF(NOT(W18=""),", "&W18&" ("&X18&")"&IF(NOT(Y18=""),", "&Y18&" ("&Z18&")"&IF(NOT(AA18=""),", "&AB18&" ("&AC18&")",""),""),""),"") -> Properties: Heavy (Creatures that are Small or Tiny have disadvantage on attack rolls with heavy weapons. A heavy weapon's size and bulk make it too large for a Small or Tiny creature to use effectively.), Reach (This weapon adds 5 feet to your reach when you attack with it. This property also determines your reach for opportunity attacks with a reach weapon.), Two-Handed (This weapon requires two hands to use. This property is relevant only when you attack with the weapon, not when you simply hold it.) | P18: {=IFERROR(_xlfn.TEXTSPLIT(G18,", ",,TRUE),"")} -> Heavy | Q18: Reach | R18: Two-Handed | U18: {=IFERROR(INDEX(_xlfn.TEXTSPLIT(P18," "),,1),"")} -> Heavy | V18: =IF(NOT(U18=""),_xlfn.XLOOKUP(U18,'weapon masteries'!$A$10:$A$19,'weapon masteries'!$B$10:$B$19,"",0),"") -> Creatures that are Small or Tiny have disadvantage on attack rolls with heavy weapons. A heavy weapon's size and bulk make it too large for a Small or Tiny creature to use effectively. | W18: {=IFERROR(INDEX(_xlfn.TEXTSPLIT(Q18," "),,1),"")} -> Reach | X18: =IF(NOT(W18=""),_xlfn.XLOOKUP(W18,'weapon masteries'!$A$10:$A$19,'weapon masteries'!$B$10:$B$19,"",0),"") -> This weapon adds 5 feet to your reach when you attack with it. This property also determines your reach for opportunity attacks with a reach weapon. | Y18: {=IFERROR(INDEX(_xlfn.TEXTSPLIT(R18," "),,1),"")} -> Two-Handed | Z18: =IF(NOT(Y18=""),_xlfn.XLOOKUP(Y18,'weapon masteries'!$A$10:$A$19,'weapon masteries'!$B$10:$B$19,"",0),"") -> This weapon requires two hands to use. This property is relevant only when you attack with the weapon, not when you simply hold it. | AA18: {=IFERROR(INDEX(_xlfn.TEXTSPLIT(S18," "),,1),"")} | AB18: =IF(NOT(AA18=""),_xlfn.XLOOKUP(AA18,'weapon masteries'!$A$10:$A$19,'weapon masteries'!$B$10:$B$19,"",0),"") | AC18: {=IFERROR(INDEX(_xlfn.TEXTSPLIT(T18," "),,1),"")} | AD18: =IF(NOT(AC18=""),_xlfn.XLOOKUP(AC18,'weapon masteries'!$A$10:$A$20,'weapon masteries'!$B$10:$B$20,"",0),"")
A19: Melee Weapon Attack | B19: Greataxe (2014 edition) | C19: Strength | D19: reach 5 ft | E19: 1d12 | F19: slashing | G19: Heavy, Two-Handed | J19: =A19&": [ATK_MOD] to hit, "&D19&", one target. Hit: [DAMAGE] "&F19&" damage. "&I19 -> Melee Weapon Attack: [ATK_MOD] to hit, reach 5 ft, one target. Hit: [DAMAGE] slashing damage. | L19: =IF(NOT(G19=""),IF(COUNTA(P19:T19)>1,"Properties: ","Property: ")&U19&" ("&V19&")"&IF(NOT(W19=""),", "&W19&" ("&X19&")"&IF(NOT(Y19=""),", "&Y19&" ("&Z19&")"&IF(NOT(AA19=""),", "&AB19&" ("&AC19&")",""),""),""),"") -> Properties: Heavy (Creatures that are Small or Tiny have disadvantage on attack rolls with heavy weapons. A heavy weapon's size and bulk make it too large for a Small or Tiny creature to use effectively.), Two-Handed (This weapon requires two hands to use. This property is relevant only when you attack with the weapon, not when you simply hold it.) | P19: {=IFERROR(_xlfn.TEXTSPLIT(G19,", ",,TRUE),"")} -> Heavy | Q19: Two-Handed | U19: {=IFERROR(INDEX(_xlfn.TEXTSPLIT(P19," "),,1),"")} -> Heavy | V19: =IF(NOT(U19=""),_xlfn.XLOOKUP(U19,'weapon masteries'!$A$10:$A$19,'weapon masteries'!$B$10:$B$19,"",0),"") -> Creatures that are Small or Tiny have disadvantage on attack rolls with heavy weapons. A heavy weapon's size and bulk make it too large for a Small or Tiny creature to use effectively. | W19: {=IFERROR(INDEX(_xlfn.TEXTSPLIT(Q19," "),,1),"")} -> Two-Handed | X19: =IF(NOT(W19=""),_xlfn.XLOOKUP(W19,'weapon masteries'!$A$10:$A$19,'weapon masteries'!$B$10:$B$19,"",0),"") -> This weapon requires two hands to use. This property is relevant only when you attack with the weapon, not when you simply hold it. | Y19: {=IFERROR(INDEX(_xlfn.TEXTSPLIT(R19," "),,1),"")} | Z19: =IF(NOT(Y19=""),_xlfn.XLOOKUP(Y19,'weapon masteries'!$A$10:$A$19,'weapon masteries'!$B$10:$B$19,"",0),"") | AA19: {=IFERROR(INDEX(_xlfn.TEXTSPLIT(S19," "),,1),"")} | AB19: =IF(NOT(AA19=""),_xlfn.XLOOKUP(AA19,'weapon masteries'!$A$10:$A$19,'weapon masteries'!$B$10:$B$19,"",0),"") | AC19: {=IFERROR(INDEX(_xlfn.TEXTSPLIT(T19," "),,1),"")} | AD19: =IF(NOT(AC19=""),_xlfn.XLOOKUP(AC19,'weapon masteries'!$A$10:$A$20,'weapon masteries'!$B$10:$B$20,"",0),"")
A20: Melee Weapon Attack | B20: Greatsword (2014 edition) | C20: Strength | D20: reach 5 ft | E20: 2d6 | F20: slashing | G20: Heavy, Two-Handed | J20: =A20&": [ATK_MOD] to hit, "&D20&", one target. Hit: [DAMAGE] "&F20&" damage. "&I20 -> Melee Weapon Attack: [ATK_MOD] to hit, reach 5 ft, one target. Hit: [DAMAGE] slashing damage. | L20: =IF(NOT(G20=""),IF(COUNTA(P20:T20)>1,"Properties: ","Property: ")&U20&" ("&V20&")"&IF(NOT(W20=""),", "&W20&" ("&X20&")"&IF(NOT(Y20=""),", "&Y20&" ("&Z20&")"&IF(NOT(AA20=""),", "&AB20&" ("&AC20&")",""),""),""),"") -> Properties: Heavy (Creatures that are Small or Tiny have disadvantage on attack rolls with heavy weapons. A heavy weapon's size and bulk make it too large for a Small or Tiny creature to use effectively.), Two-Handed (This weapon requires two hands to use. This property is relevant only when you attack with the weapon, not when you simply hold it.) | P20: {=IFERROR(_xlfn.TEXTSPLIT(G20,", ",,TRUE),"")} -> Heavy | Q20: Two-Handed | U20: {=IFERROR(INDEX(_xlfn.TEXTSPLIT(P20," "),,1),"")} -> Heavy | V20: =IF(NOT(U20=""),_xlfn.XLOOKUP(U20,'weapon masteries'!$A$10:$A$19,'weapon masteries'!$B$10:$B$19,"",0),"") -> Creatures that are Small or Tiny have disadvantage on attack rolls with heavy weapons. A heavy weapon's size and bulk make it too large for a Small or Tiny creature to use effectively. | W20: {=IFERROR(INDEX(_xlfn.TEXTSPLIT(Q20," "),,1),"")} -> Two-Handed | X20: =IF(NOT(W20=""),_xlfn.XLOOKUP(W20,'weapon masteries'!$A$10:$A$19,'weapon masteries'!$B$10:$B$19,"",0),"") -> This weapon requires two hands to use. This property is relevant only when you attack with the weapon, not when you simply hold it. | Y20: {=IFERROR(INDEX(_xlfn.TEXTSPLIT(R20," "),,1),"")} | Z20: =IF(NOT(Y20=""),_xlfn.XLOOKUP(Y20,'weapon masteries'!$A$10:$A$19,'weapon masteries'!$B$10:$B$19,"",0),"") | AA20: {=IFERROR(INDEX(_xlfn.TEXTSPLIT(S20," "),,1),"")} | AB20: =IF(NOT(AA20=""),_xlfn.XLOOKUP(AA20,'weapon masteries'!$A$10:$A$19,'weapon masteries'!$B$10:$B$19,"",0),"") | AC20: {=IFERROR(INDEX(_xlfn.TEXTSPLIT(T20," "),,1),"")} | AD20: =IF(NOT(AC20=""),_xlfn.XLOOKUP(AC20,'weapon masteries'!$A$10:$A$20,'weapon masteries'!$B$10:$B$20,"",0),"")
A21: Melee Weapon Attack | B21: Halberd (2014 edition) | C21: Strength | D21: reach 10 ft | E21: 1d10 | F21: slashing | G21: Heavy, Reach, Two-Handed | J21: =A21&": [ATK_MOD] to hit, "&D21&", one target. Hit: [DAMAGE] "&F21&" damage. "&I21 -> Melee Weapon Attack: [ATK_MOD] to hit, reach 10 ft, one target. Hit: [DAMAGE] slashing damage. | L21: =IF(NOT(G21=""),IF(COUNTA(P21:T21)>1,"Properties: ","Property: ")&U21&" ("&V21&")"&IF(NOT(W21=""),", "&W21&" ("&X21&")"&IF(NOT(Y21=""),", "&Y21&" ("&Z21&")"&IF(NOT(AA21=""),", "&AB21&" ("&AC21&")",""),""),""),"") -> Properties: Heavy (Creatures that are Small or Tiny have disadvantage on attack rolls with heavy weapons. A heavy weapon's size and bulk make it too large for a Small or Tiny creature to use effectively.), Reach (This weapon adds 5 feet to your reach when you attack with it. This property also determines your reach for opportunity attacks with a reach weapon.), Two-Handed (This weapon requires two hands to use. This property is relevant only when you attack with the weapon, not when you simply hold it.) | P21: {=IFERROR(_xlfn.TEXTSPLIT(G21,", ",,TRUE),"")} -> Heavy | Q21: Reach | R21: Two-Handed | U21: {=IFERROR(INDEX(_xlfn.TEXTSPLIT(P21," "),,1),"")} -> Heavy | V21: =IF(NOT(U21=""),_xlfn.XLOOKUP(U21,'weapon masteries'!$A$10:$A$19,'weapon masteries'!$B$10:$B$19,"",0),"") -> Creatures that are Small or Tiny have disadvantage on attack rolls with heavy weapons. A heavy weapon's size and bulk make it too large for a Small or Tiny creature to use effectively. | W21: {=IFERROR(INDEX(_xlfn.TEXTSPLIT(Q21," "),,1),"")} -> Reach | X21: =IF(NOT(W21=""),_xlfn.XLOOKUP(W21,'weapon masteries'!$A$10:$A$19,'weapon masteries'!$B$10:$B$19,"",0),"") -> This weapon adds 5 feet to your reach when you attack with it. This property also determines your reach for opportunity attacks with a reach weapon. | Y21: {=IFERROR(INDEX(_xlfn.TEXTSPLIT(R21," "),,1),"")} -> Two-Handed | Z21: =IF(NOT(Y21=""),_xlfn.XLOOKUP(Y21,'weapon masteries'!$A$10:$A$19,'weapon masteries'!$B$10:$B$19,"",0),"") -> This weapon requires two hands to use. This property is relevant only when you attack with the weapon, not when you simply hold it. | AA21: {=IFERROR(INDEX(_xlfn.TEXTSPLIT(S21," "),,1),"")} | AB21: =IF(NOT(AA21=""),_xlfn.XLOOKUP(AA21,'weapon masteries'!$A$10:$A$19,'weapon masteries'!$B$10:$B$19,"",0),"") | AC21: {=IFERROR(INDEX(_xlfn.TEXTSPLIT(T21," "),,1),"")} | AD21: =IF(NOT(AC21=""),_xlfn.XLOOKUP(AC21,'weapon masteries'!$A$10:$A$20,'weapon masteries'!$B$10:$B$20,"",0),"")
